Workbook

Sheet TT
B1: 43101
A2: Emergence | D2: =D15 -> Ace | E2: =E15 -> Aldinga | F2: =F15 -> Blitz | G2: =G15 -> Bolt | H2: =H15 -> Boomer | I2: =I15 -> CIPAL0901 | J2: =J15 -> CIPAL1504 | K2: =K15 -> CIPAL1701 | ... W2: =W15 -> Nugget
A3: =C17 -> 24AprIrrigated | B3: 43214 | C3: =B3-$B$1 -> 113 | D3: =VLOOKUP($B3+D17,MetData!$A$3:$L$793,12,FALSE)-VLOOKUP($B3,MetData!$A$3:$L$793,12,FALSE) -> 128.45 | E3: =VLOOKUP($B3+E17,MetData!$A$3:$L$793,12,FALSE)-VLOOKUP($B3,MetData!$A$3:$L$793,12,FALSE) -> 128.45 | F3: =VLOOKUP($B3+F17,MetData!$A$3:$L$793,12,FALSE)-VLOOKUP($B3,MetData!$A$3:$L$793,12,FALSE) -> 128.45 | G3: =VLOOKUP($B3+G17,MetData!$A$3:$L$793,12,FALSE)-VLOOKUP($B3,MetData!$A$3:$L$793,12,FALSE) -> 128.45 | H3: =VLOOKUP($B3+H17,MetData!$A$3:$L$793,12,FALSE)-VLOOKUP($B3,MetData!$A$3:$L$793,12,FALSE) -> 128.45 | I3: =VLOOKUP($B3+I17,MetData!$A$3:$L$793,12,FALSE)-VLOOKUP($B3,MetData!$A$3:$L$793,12,FALSE) -> 128.45 | J3: =VLOOKUP($B3+J17,MetData!$A$3:$L$793,12,FALSE)-VLOOKUP($B3,MetData!$A$3:$L$793,12,FALSE) -> 128.45 | K3: =VLOOKUP($B3+K17,MetData!$A$3:$L$793,12,FALSE)-VLOOKUP($B3,MetData!$A$3:$L$793,12,FALSE) -> 128.45 | ... W3: =VLOOKUP($B3+W17,MetData!$A$3:$L$793,12,FALSE)-VLOOKUP($B3,MetData!$A$3:$L$793,12,FALSE) -> 128.45
A4: =C18 -> 24AprRainout | B4: 43214 | C4: =B4-$B$1 -> 113 | D4: =VLOOKUP($B4+D18,MetData!$A$3:$L$793,12,FALSE)-VLOOKUP($B4,MetData!$A$3:$L$793,12,FALSE) -> 128.45 | E4: =VLOOKUP($B4+E18,MetData!$A$3:$L$793,12,FALSE)-VLOOKUP($B4,MetData!$A$3:$L$793,12,FALSE) -> 128.45 | F4: =VLOOKUP($B4+F18,MetData!$A$3:$L$793,12,FALSE)-VLOOKUP($B4,MetData!$A$3:$L$793,12,FALSE) -> 128.45 | G4: =VLOOKUP($B4+G18,MetData!$A$3:$L$793,12,FALSE)-VLOOKUP($B4,MetData!$A$3:$L$793,12,FALSE) -> 128.45 | H4: =VLOOKUP($B4+H18,MetData!$A$3:$L$793,12,FALSE)-VLOOKUP($B4,MetData!$A$3:$L$793,12,FALSE) -> 128.45 | I4: =VLOOKUP($B4+I18,MetData!$A$3:$L$793,12,FALSE)-VLOOKUP($B4,MetData!$A$3:$L$793,12,FALSE) -> 128.45 | J4: =VLOOKUP($B4+J18,MetData!$A$3:$L$793,12,FALSE)-VLOOKUP($B4,MetData!$A$3:$L$793,12,FALSE) -> 128.45 | K4: =VLOOKUP($B4+K18,MetData!$A$3:$L$793,12,FALSE)-VLOOKUP($B4,MetData!$A$3:$L$793,12,FALSE) -> 128.45 | ... W4: =VLOOKUP($B4+W18,MetData!$A$3:$L$793,12,FALSE)-VLOOKUP($B4,MetData!$A$3:$L$793,12,FALSE) -> 128.45
A5: =C19 -> 6JunIrrigated | B5: 43257 | C5: =B5-$B$1 -> 156 | D5: =VLOOKUP($B5+D19,MetData!$A$3:$L$793,12,FALSE)-VLOOKUP($B5,MetData!$A$3:$L$793,12,FALSE) -> 124.55 | E5: =VLOOKUP($B5+E19,MetData!$A$3:$L$793,12,FALSE)-VLOOKUP($B5,MetData!$A$3:$L$793,12,FALSE) -> 124.55 | F5: =VLOOKUP($B5+F19,MetData!$A$3:$L$793,12,FALSE)-VLOOKUP($B5,MetData!$A$3:$L$793,12,FALSE) -> 124.55 | G5: =VLOOKUP($B5+G19,MetData!$A$3:$L$793,12,FALSE)-VLOOKUP($B5,MetData!$A$3:$L$793,12,FALSE) -> 124.55 | H5: =VLOOKUP($B5+H19,MetData!$A$3:$L$793,12,FALSE)-VLOOKUP($B5,MetData!$A$3:$L$793,12,FALSE) -> 124.55 | I5: =VLOOKUP($B5+I19,MetData!$A$3:$L$793,12,FALSE)-VLOOKUP($B5,MetData!$A$3:$L$793,12,FALSE) -> 124.55 | J5: =VLOOKUP($B5+J19,MetData!$A$3:$L$793,12,FALSE)-VLOOKUP($B5,MetData!$A$3:$L$793,12,FALSE) -> 124.55 | K5: =VLOOKUP($B5+K19,MetData!$A$3:$L$793,12,FALSE)-VLOOKUP($B5,MetData!$A$3:$L$793,12,FALSE) -> 124.55 | ... W5: =VLOOKUP($B5+W19,MetData!$A$3:$L$793,12,FALSE)-VLOOKUP($B5,MetData!$A$3:$L$793,12,FALSE) -> 124.55
A6: =C20 -> 6JunRainfed | B6: 43257 | C6: =B6-$B$1 -> 156 | D6: =VLOOKUP($B6+D20,MetData!$A$3:$L$793,12,FALSE)-VLOOKUP($B6,MetData!$A$3:$L$793,12,FALSE) -> 124.55 | E6: =VLOOKUP($B6+E20,MetData!$A$3:$L$793,12,FALSE)-VLOOKUP($B6,MetData!$A$3:$L$793,12,FALSE) -> 124.55 | F6: =VLOOKUP($B6+F20,MetData!$A$3:$L$793,12,FALSE)-VLOOKUP($B6,MetData!$A$3:$L$793,12,FALSE) -> 124.55 | G6: =VLOOKUP($B6+G20,MetData!$A$3:$L$793,12,FALSE)-VLOOKUP($B6,MetData!$A$3:$L$793,12,FALSE) -> 124.55 | H6: =VLOOKUP($B6+H20,MetData!$A$3:$L$793,12,FALSE)-VLOOKUP($B6,MetData!$A$3:$L$793,12,FALSE) -> 124.55 | I6: =VLOOKUP($B6+I20,MetData!$A$3:$L$793,12,FALSE)-VLOOKUP($B6,MetData!$A$3:$L$793,12,FALSE) -> 124.55 | J6: =VLOOKUP($B6+J20,MetData!$A$3:$L$793,12,FALSE)-VLOOKUP($B6,MetData!$A$3:$L$793,12,FALSE) -> 124.55 | K6: =VLOOKUP($B6+K20,MetData!$A$3:$L$793,12,FALSE)-VLOOKUP($B6,MetData!$A$3:$L$793,12,FALSE) -> 124.55 | ... W6: =VLOOKUP($B6+W20,MetData!$A$3:$L$793,12,FALSE)-VLOOKUP($B6,MetData!$A$3:$L$793,12,FALSE) -> 124.55
A8: =C22 -> 29AprIrrigated | B8: 43584 | C8: =B8-$B$1-365 -> 118 | D8: =VLOOKUP($B8+D22,MetData!$A$3:$L$793,12,FALSE)-VLOOKUP($B8,MetData!$A$3:$L$793,12,FALSE) -> 131.1 | E8: =VLOOKUP($B8+E22,MetData!$A$3:$L$793,12,FALSE)-VLOOKUP($B8,MetData!$A$3:$L$793,12,FALSE) -> 131.1 | F8: =VLOOKUP($B8+F22,MetData!$A$3:$L$793,12,FALSE)-VLOOKUP($B8,MetData!$A$3:$L$793,12,FALSE) -> 131.1 | G8: =VLOOKUP($B8+G22,MetData!$A$3:$L$793,12,FALSE)-VLOOKUP($B8,MetData!$A$3:$L$793,12,FALSE) -> 131.1 | H8: =VLOOKUP($B8+H22,MetData!$A$3:$L$793,12,FALSE)-VLOOKUP($B8,MetData!$A$3:$L$793,12,FALSE) -> 131.1 | I8: =VLOOKUP($B8+I22,MetData!$A$3:$L$793,12,FALSE)-VLOOKUP($B8,MetData!$A$3:$L$793,12,FALSE) -> 131.1 | J8: =VLOOKUP($B8+J22,MetData!$A$3:$L$793,12,FALSE)-VLOOKUP($B8,MetData!$A$3:$L$793,12,FALSE) -> 131.1 | K8: =VLOOKUP($B8+K22,MetData!$A$3:$L$793,12,FALSE)-VLOOKUP($B8,MetData!$A$3:$L$793,12,FALSE) -> 131.1 | ... W8: =VLOOKUP($B8+W22,MetData!$A$3:$L$793,12,FALSE)-VLOOKUP($B8,MetData!$A$3:$L$793,12,FALSE) -> 131.1
A9: =C23 -> 29AprRainout | B9: 43584 | C9: =B9-$B$1-365 -> 118 | D9: =VLOOKUP($B9+D23,MetData!$A$3:$L$793,12,FALSE)-VLOOKUP($B9,MetData!$A$3:$L$793,12,FALSE) -> 131.1 | E9: =VLOOKUP($B9+E23,MetData!$A$3:$L$793,12,FALSE)-VLOOKUP($B9,MetData!$A$3:$L$793,12,FALSE) -> 131.1 | F9: =VLOOKUP($B9+F23,MetData!$A$3:$L$793,12,FALSE)-VLOOKUP($B9,MetData!$A$3:$L$793,12,FALSE) -> 131.1 | G9: =VLOOKUP($B9+G23,MetData!$A$3:$L$793,12,FALSE)-VLOOKUP($B9,MetData!$A$3:$L$793,12,FALSE) -> 131.1 | H9: =VLOOKUP($B9+H23,MetData!$A$3:$L$793,12,FALSE)-VLOOKUP($B9,MetData!$A$3:$L$793,12,FALSE) -> 131.1 | I9: =VLOOKUP($B9+I23,MetData!$A$3:$L$793,12,FALSE)-VLOOKUP($B9,MetData!$A$3:$L$793,12,FALSE) -> 131.1 | J9: =VLOOKUP($B9+J23,MetData!$A$3:$L$793,12,FALSE)-VLOOKUP($B9,MetData!$A$3:$L$793,12,FALSE) -> 131.1 | K9: =VLOOKUP($B9+K23,MetData!$A$3:$L$793,12,FALSE)-VLOOKUP($B9,MetData!$A$3:$L$793,12,FALSE) -> 131.1 | ... W9: =VLOOKUP($B9+W23,MetData!$A$3:$L$793,12,FALSE)-VLOOKUP($B9,MetData!$A$3:$L$793,12,FALSE) -> 131.1
A10: =C24 -> 24JunIrrigated | B10: 43640 | C10: =B10-$B$1-365 -> 174 | D10: =VLOOKUP($B10+D24,MetData!$A$3:$L$793,12,FALSE)-VLOOKUP($B10,MetData!$A$3:$L$793,12,FALSE) -> 133.6 | E10: =VLOOKUP($B10+E24,MetData!$A$3:$L$793,12,FALSE)-VLOOKUP($B10,MetData!$A$3:$L$793,12,FALSE) -> 133.6 | F10: =VLOOKUP($B10+F24,MetData!$A$3:$L$793,12,FALSE)-VLOOKUP($B10,MetData!$A$3:$L$793,12,FALSE) -> 133.6 | G10: =VLOOKUP($B10+G24,MetData!$A$3:$L$793,12,FALSE)-VLOOKUP($B10,MetData!$A$3:$L$793,12,FALSE) -> 133.6 | H10: =VLOOKUP($B10+H24,MetData!$A$3:$L$793,12,FALSE)-VLOOKUP($B10,MetData!$A$3:$L$793,12,FALSE) -> 133.6 | I10: =VLOOKUP($B10+I24,MetData!$A$3:$L$793,12,FALSE)-VLOOKUP($B10,MetData!$A$3:$L$793,12,FALSE) -> 133.6 | J10: =VLOOKUP($B10+J24,MetData!$A$3:$L$793,12,FALSE)-VLOOKUP($B10,MetData!$A$3:$L$793,12,FALSE) -> 133.6 | K10: =VLOOKUP($B10+K24,MetData!$A$3:$L$793,12,FALSE)-VLOOKUP($B10,MetData!$A$3:$L$793,12,FALSE) -> 133.6 | ... W10: =VLOOKUP($B10+W24,MetData!$A$3:$L$793,12,FALSE)-VLOOKUP($B10,MetData!$A$3:$L$793,12,FALSE) -> 133.6
A11: =C25 -> 24JunRainfed | B11: 43640 | C11: =B11-$B$1-365 -> 174 | D11: =VLOOKUP($B11+D25,MetData!$A$3:$L$793,12,FALSE)-VLOOKUP($B11,MetData!$A$3:$L$793,12,FALSE) -> 133.6 | E11: =VLOOKUP($B11+E25,MetData!$A$3:$L$793,12,FALSE)-VLOOKUP($B11,MetData!$A$3:$L$793,12,FALSE) -> 133.6 | F11: =VLOOKUP($B11+F25,MetData!$A$3:$L$793,12,FALSE)-VLOOKUP($B11,MetData!$A$3:$L$793,12,FALSE) -> 133.6 | G11: =VLOOKUP($B11+G25,MetData!$A$3:$L$793,12,FALSE)-VLOOKUP($B11,MetData!$A$3:$L$793,12,FALSE) -> 133.6 | H11: =VLOOKUP($B11+H25,MetData!$A$3:$L$793,12,FALSE)-VLOOKUP($B11,MetData!$A$3:$L$793,12,FALSE) -> 133.6 | I11: =VLOOKUP($B11+I25,MetData!$A$3:$L$793,12,FALSE)-VLOOKUP($B11,MetData!$A$3:$L$793,12,FALSE) -> 133.6 | J11: =VLOOKUP($B11+J25,MetData!$A$3:$L$793,12,FALSE)-VLOOKUP($B11,MetData!$A$3:$L$793,12,FALSE) -> 133.6 | K11: =VLOOKUP($B11+K25,MetData!$A$3:$L$793,12,FALSE)-VLOOKUP($B11,MetData!$A$3:$L$793,12,FALSE) -> 133.6 | ... W11: =VLOOKUP($B11+W25,MetData!$A$3:$L$793,12,FALSE)-VLOOKUP($B11,MetData!$A$3:$L$793,12,FALSE) -> 133.6
C14: Sum of Lentil.Phenology.EmergenceDAS | D14: Column Labels
C15: Row Labels | D15: Ace | E15: Aldinga | F15: Blitz | G15: Bolt | H15: Boomer | I15: CIPAL0901 | J15: CIPAL1504 | K15: CIPAL1701 | L15: Commando | M15: Flash | N15: Giant | O15: Greenfield | P15: Hurricane | Q15: Indianhead | R15: Jumbo | S15: Jumbo2 | T15: Matilda | U15: Nipper | V15: Northfield | W15: Nugget
C16: Roseworthy2018
C17: 24AprIrrigated | D17: 9 | E17: 9 | F17: 9 | G17: 9 | H17: 9 | I17: 9 | J17: 9 | K17: 9 | L17: 9 | M17: 9 | N17: 9 | O17: 9 | P17: 9 | Q17: 9 | R17: 9 | S17: 9 | T17: 9 | U17: 9 | V17: 9 | W17: 9
C18: 24AprRainout | D18: 9 | E18: 9 | F18: 9 | G18: 9 | H18: 9 | I18: 9 | J18: 9 | K18: 9 | L18: 9 | M18: 9 | N18: 9 | O18: 9 | P18: 9 | Q18: 9 | R18: 9 | S18: 9 | T18: 9 | U18: 9 | V18: 9 | W18: 9
C19: 6JunIrrigated | D19: 13 | E19: 13 | F19: 13 | G19: 13 | H19: 13 | I19: 13 | J19: 13 | K19: 13 | L19: 13 | M19: 13 | N19: 13 | O19: 13 | P19: 13 | Q19: 13 | R19: 13 | S19: 13 | T19: 13 | U19: 13 | V19: 13 | W19: 13
C20: 6JunRainfed | D20: 13 | E20: 13 | F20: 13 | G20: 13 | H20: 13 | I20: 13 | J20: 13 | K20: 13 | L20: 13 | M20: 13 | N20: 13 | O20: 13 | P20: 13 | Q20: 13 | R20: 13 | S20: 13 | T20: 13 | U20: 13 | V20: 13 | W20: 13
C21: Roseworthy2019
C22: 29AprIrrigated | D22: 12 | E22: 12 | F22: 12 | G22: 12 | H22: 12 | I22: 12 | J22: 12 | K22: 12 | L22: 12 | M22: 12 | N22: 12 | O22: 12 | P22: 12 | Q22: 12 | R22: 12 | S22: 12 | T22: 12 | U22: 12 | V22: 12 | W22: 12
C23: 29AprRainout | D23: 12 | E23: 12 | F23: 12 | G23: 12 | H23: 12 | I23: 12 | J23: 12 | K23: 12 | L23: 12 | M23: 12 | N23: 12 | O23: 12 | P23: 12 | Q23: 12 | R23: 12 | S23: 12 | T23: 12 | U23: 12 | V23: 12 | W23: 12
C24: 24JunIrrigated | D24: 14 | E24: 14 | F24: 14 | G24: 14 | H24: 14 | I24: 14 | J24: 14 | K24: 14 | L24: 14 | M24: 14 | N24: 14 | O24: 14 | P24: 14 | Q24: 14 | R24: 14 | S24: 14 | T24: 14 | U24: 14 | V24: 14 | W24: 14
C25: 24JunRainfed | D25: 14 | E25: 14 | F25: 14 | G25: 14 | H25: 14 | I25: 14 | J25: 14 | K25: 14 | L25: 14 | M25: 14 | N25: 14 | O25: 14 | P25: 14 | Q25: 14 | R25: 14 | S25: 14 | T25: 14 | U25: 14 | V25: 14 | W25: 14
A27: Emergence to flowering | D27: =D40 -> Ace | E27: =E40 -> Aldinga | F27: =F40 -> Blitz | G27: =G40 -> Bolt | H27: =H40 -> Boomer | I27: =I40 -> CIPAL0901 | J27: =J40 -> CIPAL1504 | K27: =K40 -> CIPAL1701 | ... W27: =W40 -> Nugget
A28: =C42 -> 24AprIrrigated | B28: 43214 | C28: =B28-$B$1 -> 113 | D28: =VLOOKUP($B28+ROUND(D42,0),MetData!$A$3:$L$793,12,FALSE)-VLOOKUP($B28,MetData!$A$3:$L$793,12,FALSE)-D3 -> 841.5 | E28: =VLOOKUP($B28+ROUND(E42,0),MetData!$A$3:$L$793,12,FALSE)-VLOOKUP($B28,MetData!$A$3:$L$793,12,FALSE)-E3 -> 1068.2 | F28: =VLOOKUP($B28+ROUND(F42,0),MetData!$A$3:$L$793,12,FALSE)-VLOOKUP($B28,MetData!$A$3:$L$793,12,FALSE)-F3 -> 760.2 | G28: =VLOOKUP($B28+ROUND(G42,0),MetData!$A$3:$L$793,12,FALSE)-VLOOKUP($B28,MetData!$A$3:$L$793,12,FALSE)-G3 -> 862.1 | H28: =VLOOKUP($B28+ROUND(H42,0),MetData!$A$3:$L$793,12,FALSE)-VLOOKUP($B28,MetData!$A$3:$L$793,12,FALSE)-H3 -> 958.55 | I28: =VLOOKUP($B28+ROUND(I42,0),MetData!$A$3:$L$793,12,FALSE)-VLOOKUP($B28,MetData!$A$3:$L$793,12,FALSE)-I3 -> 831.1 | J28: =VLOOKUP($B28+ROUND(J42,0),MetData!$A$3:$L$793,12,FALSE)-VLOOKUP($B28,MetData!$A$3:$L$793,12,FALSE)-J3 -> 935.35 | K28: =VLOOKUP($B28+ROUND(K42,0),MetData!$A$3:$L$793,12,FALSE)-VLOOKUP($B28,MetData!$A$3:$L$793,12,FALSE)-K3 -> 853.65 | ... W28: =VLOOKUP($B28+ROUND(W42,0),MetData!$A$3:$L$793,12,FALSE)-VLOOKUP($B28,MetData!$A$3:$L$793,12,FALSE)-W3 -> 1061.5 | AG28: Negative means dry treatments are flowering earlier that irrigated
A29: =C47 -> 29AprIrrigated | B29: 43584 | C29: =B29-$B$1-365 -> 118 | D29: =VLOOKUP($B29+ROUND(D43,0),MetData!$A$3:$L$793,12,FALSE)-VLOOKUP($B29,MetData!$A$3:$L$793,12,FALSE)-D4 -> 855.6 | E29: =VLOOKUP($B29+ROUND(E43,0),MetData!$A$3:$L$793,12,FALSE)-VLOOKUP($B29,MetData!$A$3:$L$793,12,FALSE)-E4 -> 1001.4 | F29: =VLOOKUP($B29+ROUND(F43,0),MetData!$A$3:$L$793,12,FALSE)-VLOOKUP($B29,MetData!$A$3:$L$793,12,FALSE)-F4 -> 759.5 | G29: =VLOOKUP($B29+ROUND(G43,0),MetData!$A$3:$L$793,12,FALSE)-VLOOKUP($B29,MetData!$A$3:$L$793,12,FALSE)-G4 -> 835.45 | H29: =VLOOKUP($B29+ROUND(H43,0),MetData!$A$3:$L$793,12,FALSE)-VLOOKUP($B29,MetData!$A$3:$L$793,12,FALSE)-H4 -> 808.65 | I29: =VLOOKUP($B29+ROUND(I43,0),MetData!$A$3:$L$793,12,FALSE)-VLOOKUP($B29,MetData!$A$3:$L$793,12,FALSE)-I4 -> 784.7 | J29: =VLOOKUP($B29+ROUND(J43,0),MetData!$A$3:$L$793,12,FALSE)-VLOOKUP($B29,MetData!$A$3:$L$793,12,FALSE)-J4 -> 883.25 | K29: =VLOOKUP($B29+ROUND(K43,0),MetData!$A$3:$L$793,12,FALSE)-VLOOKUP($B29,MetData!$A$3:$L$793,12,FALSE)-K4 -> 818.9 | M29: =VLOOKUP($B29+ROUND(M43,0),MetData!$A$3:$L$793,12,FALSE)-VLOOKUP($B29,MetData!$A$3:$L$793,12,FALSE)-M4 -> 962.5 | N29: =VLOOKUP($B29+ROUND(N43,0),MetData!$A$3:$L$793,12,FALSE)-VLOOKUP($B29,MetData!$A$3:$L$793,12,FALSE)-N4 -> 808.65 | O29: =VLOOKUP($B29+ROUND(O43,0),MetData!$A$3:$L$793,12,FALSE)-VLOOKUP($B29,MetData!$A$3:$L$793,12,FALSE)-O4 -> 855.6 | P29: =VLOOKUP($B29+ROUND(P43,0),MetData!$A$3:$L$793,12,FALSE)-VLOOKUP($B29,MetData!$A$3:$L$793,12,FALSE)-P4 -> 847.7 | Q29: =VLOOKUP($B29+ROUND(Q43,0),MetData!$A$3:$L$793,12,FALSE)-VLOOKUP($B29,MetData!$A$3:$L$793,12,FALSE)-Q4 -> 1086.5 | R29: =VLOOKUP($B29+ROUND(R43,0),MetData!$A$3:$L$793,12,FALSE)-VLOOKUP($B29,MetData!$A$3:$L$793,12,FALSE)-R4 -> 987.65 | S29: =VLOOKUP($B29+ROUND(S43,0),MetData!$A$3:$L$793,12,FALSE)-VLOOKUP($B29,MetData!$A$3:$L$793,12,FALSE)-S4 -> 818.9 | T29: =VLOOKUP($B29+ROUND(T43,0),MetData!$A$3:$L$793,12,FALSE)-VLOOKUP($B29,MetData!$A$3:$L$793,12,FALSE)-T4 -> 883.25 | ... W29: =VLOOKUP($B29+ROUND(W43,0),MetData!$A$3:$L$793,12,FALSE)-VLOOKUP($B29,MetData!$A$3:$L$793,12,FALSE)-W4 -> 993.5
A30: =C44 -> 6JunIrrigated | B30: 43257 | C30: =B30-$B$1 -> 156 | D30: =VLOOKUP($B30+ROUND(D44,0),MetData!$A$3:$L$793,12,FALSE)-VLOOKUP($B30,MetData!$A$3:$L$793,12,FALSE)-D5 -> 780.65 | E30: =VLOOKUP($B30+ROUND(E44,0),MetData!$A$3:$L$793,12,FALSE)-VLOOKUP($B30,MetData!$A$3:$L$793,12,FALSE)-E5 -> 807.25 | F30: =VLOOKUP($B30+ROUND(F44,0),MetData!$A$3:$L$793,12,FALSE)-VLOOKUP($B30,MetData!$A$3:$L$793,12,FALSE)-F5 -> 740.45 | G30: =VLOOKUP($B30+ROUND(G44,0),MetData!$A$3:$L$793,12,FALSE)-VLOOKUP($B30,MetData!$A$3:$L$793,12,FALSE)-G5 -> 772.85 | H30: =VLOOKUP($B30+ROUND(H44,0),MetData!$A$3:$L$793,12,FALSE)-VLOOKUP($B30,MetData!$A$3:$L$793,12,FALSE)-H5 -> 780.65 | I30: =VLOOKUP($B30+ROUND(I44,0),MetData!$A$3:$L$793,12,FALSE)-VLOOKUP($B30,MetData!$A$3:$L$793,12,FALSE)-I5 -> 713.45 | J30: =VLOOKUP($B30+ROUND(J44,0),MetData!$A$3:$L$793,12,FALSE)-VLOOKUP($B30,MetData!$A$3:$L$793,12,FALSE)-J5 -> 797.2 | K30: =VLOOKUP($B30+ROUND(K44,0),MetData!$A$3:$L$793,12,FALSE)-VLOOKUP($B30,MetData!$A$3:$L$793,12,FALSE)-K5 -> 713.45 | ... W30: =VLOOKUP($B30+ROUND(W44,0),MetData!$A$3:$L$793,12,FALSE)-VLOOKUP($B30,MetData!$A$3:$L$793,12,FALSE)-W5 -> 807.25
A31: =C49 -> 24JunIrrigated | B31: 43640 | C31: =B31-$B$1-365 -> 174 | D31: =VLOOKUP($B31+ROUND(D45,0),MetData!$A$3:$L$793,12,FALSE)-VLOOKUP($B31,MetData!$A$3:$L$793,12,FALSE)-D6 -> 850.6 | E31: =VLOOKUP($B31+ROUND(E45,0),MetData!$A$3:$L$793,12,FALSE)-VLOOKUP($B31,MetData!$A$3:$L$793,12,FALSE)-E6 -> 888.55 | F31: =VLOOKUP($B31+ROUND(F45,0),MetData!$A$3:$L$793,12,FALSE)-VLOOKUP($B31,MetData!$A$3:$L$793,12,FALSE)-F6 -> 721.65 | G31: =VLOOKUP($B31+ROUND(G45,0),MetData!$A$3:$L$793,12,FALSE)-VLOOKUP($B31,MetData!$A$3:$L$793,12,FALSE)-G6 -> 815.85 | H31: =VLOOKUP($B31+ROUND(H45,0),MetData!$A$3:$L$793,12,FALSE)-VLOOKUP($B31,MetData!$A$3:$L$793,12,FALSE)-H6 -> 795.05 | I31: =VLOOKUP($B31+ROUND(I45,0),MetData!$A$3:$L$793,12,FALSE)-VLOOKUP($B31,MetData!$A$3:$L$793,12,FALSE)-I6 -> 734.9 | J31: =VLOOKUP($B31+ROUND(J45,0),MetData!$A$3:$L$793,12,FALSE)-VLOOKUP($B31,MetData!$A$3:$L$793,12,FALSE)-J6 -> 830.45 | K31: =VLOOKUP($B31+ROUND(K45,0),MetData!$A$3:$L$793,12,FALSE)-VLOOKUP($B31,MetData!$A$3:$L$793,12,FALSE)-K6 -> 734.9 | ... W31: =VLOOKUP($B31+ROUND(W45,0),MetData!$A$3:$L$793,12,FALSE)-VLOOKUP($B31,MetData!$A$3:$L$793,12,FALSE)-W6 -> 888.55
C39: Average of Lentil.Phenology.StartOfFloweringDAS | D39: Column Labels
C40: Row Labels | D40: Ace | E40: Aldinga | F40: Blitz | G40: Bolt | H40: Boomer | I40: CIPAL0901 | J40: CIPAL1504 | K40: CIPAL1701 | L40: Commando | M40: Flash | N40: Giant | O40: Greenfield | P40: Hurricane | Q40: Indianhead | R40: Jumbo | S40: Jumbo2 | T40: Matilda | U40: Nipper | V40: Northfield | W40: Nugget
C41: Roseworthy2018
C42: 24AprIrrigated | D42: 99 | E42: 125.33333 | F42: 91 | G42: 100.66667 | H42: 111.66667 | I42: 98 | J42: 109.33333 | K42: 100.33333 | L42: 147.33333 | M42: 116.33333 | N42: 97 | O42: 113.66667 | P42: 104.66667 | Q42: 150 | R42: 124 | S42: 112 | T42: 116.66667 | U42: 137 | V42: 138.33333 | W42: 124.33333
C43: 24AprRainout | D43: 104.33333 | E43: 123 | F43: 91.333333 | G43: 101 | H43: 98 | I43: 95.333333 | J43: 108 | K43: 98.666667 | M43: 117.33333 | N43: 98.333333 | O43: 104.33333 | P43: 103 | Q43: 131.33333 | R43: 121 | S43: 99.333333 | T43: 108.33333 | U43: 126 | V43: 128 | W43: 122
C44: 6JunIrrigated | D44: 101.33333 | E44: 103.66667 | F44: 97 | G44: 100.33333 | H44: 100.66667 | I44: 95.333333 | J44: 103.33333 | K44: 95.333333 | L44: 124 | M44: 103.66667 | N44: 100.66667 | O44: 102.33333 | P44: 104.66667 | Q44: 119 | R44: 101.66667 | S44: 99.666667 | T44: 102.33333 | U44: 105.66667 | V44: 104.33333 | W44: 103.66667
C45: 6JunRainfed | D45: 102 | E45: 103.66667 | F45: 93.333333 | G45: 100.33333 | H45: 99 | I45: 94 | J45: 101.33333 | K45: 93.666667 | L45: 125 | M45: 99 | N45: 96.333333 | O45: 102.66667 | P45: 103.33333 | Q45: 122.33333 | R45: 101.33333 | S45: 100.66667 | T45: 102 | U45: 106.33333 | V45: 104.66667 | W45: 104
C46: Roseworthy2019
C47: 29AprIrrigated | D47: 116.33333 | E47: 130 | F47: 99 | G47: 114.33333 | H47: 122.66667 | I47: 105.33333 | J47: 119.33333 | K47: 95.666667 | L47: 162 | M47: 119 | N47: 111.33333 | O47: 116.33333 | P47: 118.33333 | Q47: 157.66667 | R47: 119.66667 | S47: 119.66667 | T47: 125.33333 | U47: 132 | V47: 134 | W47: 126
C48: 29AprRainout | D48: 115.66667 | E48: 123 | F48: 101 | G48: 112 | H48: 121 | I48: 103.66667 | J48: 117.33333 | K48: 99.333333 | L48: 145.33333 | M48: 119 | N48: 111 | O48: 123 | P48: 114.66667 | Q48: 137.66667 | R48: 116.33333 | S48: 117.66667 | T48: 116.66667 | U48: 125.33333 | V48: 130.33333 | W48: 122.33333
C49: 24JunIrrigated | D49: 90.333333 | E49: 95.5 | F49: 85.666667 | G49: 88 | H49: 92.5 | I49: 86.666667 | J49: 89 | K49: 84 | L49: 101.5 | M49: 88.5 | N49: 89 | O49: 95.333333 | P49: 89 | Q49: 104 | R49: 92.333333 | S49: 86.5 | T49: 88.75 | U49: 92.333333 | V49: 99 | W49: 90.5
C50: 24JunRainfed | D50: 96 | E50: 98.333333 | F50: 89.333333 | G50: 96 | H50: 107.33333 | I50: 93 | J50: 98.666667 | K50: 85.666667 | L50: 100.33333 | M50: 105 | N50: 93 | O50: 97.333333 | P50: 99 | Q50: 116 | R50: 96.666667 | S50: 97 | U50: 100 | V50: 99.666667 | W50: 96
A53: Flowering to Pod emergence | D53: =D66 -> Ace | E53: =E66 -> Aldinga | F53: =F66 -> Blitz | G53: =G66 -> Bolt | H53: =H66 -> Boomer | I53: =I66 -> CIPAL0901 | J53: =J66 -> CIPAL1504 | K53: =K66 -> CIPAL1701 | ... W53: =W66 -> Nugget
...

Sheet DAS
B1: 45292
A2: Emergence | D2: =D15 -> Ace | E2: =E15 -> Aldinga | F2: =F15 -> Blitz | G2: =G15 -> Bolt | H2: =H15 -> Boomer | I2: =I15 -> CIPAL0901 | J2: =J15 -> CIPAL1504 | K2: =K15 -> CIPAL1701 | ... W2: =W15 -> Nugget
A3: =C17 -> 24AprIrrigated | B3: 45406 | C3: =B3-$B$1 -> 114 | D3: =D17 -> 9 | E3: =E17 -> 9 | F3: =F17 -> 9 | G3: =G17 -> 9 | H3: =H17 -> 9 | I3: =I17 -> 9 | J3: =J17 -> 9 | K3: =K17 -> 9 | ... W3: =W17 -> 9
A4: =C18 -> 24AprRainout | B4: 45406 | C4: =B4-$B$1 -> 114 | D4: =D18 -> 9 | E4: =E18 -> 9 | F4: =F18 -> 9 | G4: =G18 -> 9 | H4: =H18 -> 9 | I4: =I18 -> 9 | J4: =J18 -> 9 | K4: =K18 -> 9 | ... W4: =W18 -> 9
A5: =C19 -> 6JunIrrigated | B5: 45449 | C5: =B5-$B$1 -> 157 | D5: =D19 -> 13 | E5: =E19 -> 13 | F5: =F19 -> 13 | G5: =G19 -> 13 | H5: =H19 -> 13 | I5: =I19 -> 13 | J5: =J19 -> 13 | K5: =K19 -> 13 | ... W5: =W19 -> 13
A6: =C20 -> 6JunRainfed | B6: 45449 | C6: =B6-$B$1 -> 157 | D6: =D20 -> 13 | E6: =E20 -> 13 | F6: =F20 -> 13 | G6: =G20 -> 13 | H6: =H20 -> 13 | I6: =I20 -> 13 | J6: =J20 -> 13 | K6: =K20 -> 13 | ... W6: =W20 -> 13
A8: =C22 -> 29AprIrrigated | B8: 45411 | C8: =B8-$B$1 -> 119 | D8: =D22 -> 12 | E8: =E22 -> 12 | F8: =F22 -> 12 | G8: =G22 -> 12 | H8: =H22 -> 12 | I8: =I22 -> 12 | J8: =J22 -> 12 | K8: =K22 -> 12 | ... W8: =W22 -> 12
A9: =C23 -> 29AprRainout | B9: 45411 | C9: =B9-$B$1 -> 119 | D9: =D23 -> 12 | E9: =E23 -> 12 | F9: =F23 -> 12 | G9: =G23 -> 12 | H9: =H23 -> 12 | I9: =I23 -> 12 | J9: =J23 -> 12 | K9: =K23 -> 12 | ... W9: =W23 -> 12
A10: =C24 -> 24JunIrrigated | B10: 45467 | C10: =B10-$B$1 -> 175 | D10: =D24 -> 14 | E10: =E24 -> 14 | F10: =F24 -> 14 | G10: =G24 -> 14 | H10: =H24 -> 14 | I10: =I24 -> 14 | J10: =J24 -> 14 | K10: =K24 -> 14 | ... W10: =W24 -> 14
A11: =C25 -> 24JunRainfed | B11: 45467 | C11: =B11-$B$1 -> 175 | D11: =D25 -> 14 | E11: =E25 -> 14 | F11: =F25 -> 14 | G11: =G25 -> 14 | H11: =H25 -> 14 | I11: =I25 -> 14 | J11: =J25 -> 14 | K11: =K25 -> 14 | ... W11: =W25 -> 14
C14: Sum of Lentil.Phenology.EmergenceDAS | D14: Column Labels
C15: Row Labels | D15: Ace | E15: Aldinga | F15: Blitz | G15: Bolt | H15: Boomer | I15: CIPAL0901 | J15: CIPAL1504 | K15: CIPAL1701 | L15: Commando | M15: Flash | N15: Giant | O15: Greenfield | P15: Hurricane | Q15: Indianhead | R15: Jumbo | S15: Jumbo2 | T15: Matilda | U15: Nipper | V15: Northfield | W15: Nugget
C16: Roseworthy2018
C17: 24AprIrrigated | D17: 9 | E17: 9 | F17: 9 | G17: 9 | H17: 9 | I17: 9 | J17: 9 | K17: 9 | L17: 9 | M17: 9 | N17: 9 | O17: 9 | P17: 9 | Q17: 9 | R17: 9 | S17: 9 | T17: 9 | U17: 9 | V17: 9 | W17: 9
C18: 24AprRainout | D18: 9 | E18: 9 | F18: 9 | G18: 9 | H18: 9 | I18: 9 | J18: 9 | K18: 9 | L18: 9 | M18: 9 | N18: 9 | O18: 9 | P18: 9 | Q18: 9 | R18: 9 | S18: 9 | T18: 9 | U18: 9 | V18: 9 | W18: 9
C19: 6JunIrrigated | D19: 13 | E19: 13 | F19: 13 | G19: 13 | H19: 13 | I19: 13 | J19: 13 | K19: 13 | L19: 13 | M19: 13 | N19: 13 | O19: 13 | P19: 13 | Q19: 13 | R19: 13 | S19: 13 | T19: 13 | U19: 13 | V19: 13 | W19: 13
C20: 6JunRainfed | D20: 13 | E20: 13 | F20: 13 | G20: 13 | H20: 13 | I20: 13 | J20: 13 | K20: 13 | L20: 13 | M20: 13 | N20: 13 | O20: 13 | P20: 13 | Q20: 13 | R20: 13 | S20: 13 | T20: 13 | U20: 13 | V20: 13 | W20: 13
C21: Roseworthy2019
C22: 29AprIrrigated | D22: 12 | E22: 12 | F22: 12 | G22: 12 | H22: 12 | I22: 12 | J22: 12 | K22: 12 | L22: 12 | M22: 12 | N22: 12 | O22: 12 | P22: 12 | Q22: 12 | R22: 12 | S22: 12 | T22: 12 | U22: 12 | V22: 12 | W22: 12
C23: 29AprRainout | D23: 12 | E23: 12 | F23: 12 | G23: 12 | H23: 12 | I23: 12 | J23: 12 | K23: 12 | L23: 12 | M23: 12 | N23: 12 | O23: 12 | P23: 12 | Q23: 12 | R23: 12 | S23: 12 | T23: 12 | U23: 12 | V23: 12 | W23: 12
C24: 24JunIrrigated | D24: 14 | E24: 14 | F24: 14 | G24: 14 | H24: 14 | I24: 14 | J24: 14 | K24: 14 | L24: 14 | M24: 14 | N24: 14 | O24: 14 | P24: 14 | Q24: 14 | R24: 14 | S24: 14 | T24: 14 | U24: 14 | V24: 14 | W24: 14
C25: 24JunRainfed | D25: 14 | E25: 14 | F25: 14 | G25: 14 | H25: 14 | I25: 14 | J25: 14 | K25: 14 | L25: 14 | M25: 14 | N25: 14 | O25: 14 | P25: 14 | Q25: 14 | R25: 14 | S25: 14 | T25: 14 | U25: 14 | V25: 14 | W25: 14
A27: Emergence to flowering | D27: =D40 -> Ace | E27: =E40 -> Aldinga | F27: =F40 -> Blitz | G27: =G40 -> Bolt | H27: =H40 -> Boomer | I27: =I40 -> CIPAL0901 | J27: =J40 -> CIPAL1504 | K27: =K40 -> CIPAL1701 | ... W27: =W40 -> Nugget
A28: =C42 -> 24AprIrrigated | B28: 45406 | C28: =B28-$B$1 -> 114 | D28: =D42-D3 -> 90 | E28: =E42-E3 -> 116.33333 | F28: =F42-F3 -> 82 | G28: =G42-G3 -> 91.666667 | H28: =H42-H3 -> 102.66667 | I28: =I42-I3 -> 89 | J28: =J42-J3 -> 100.33333 | K28: =K42-K3 -> 91.333333 | ... W28: =W42-W3 -> 115.33333 | AG28: Negative means dry treatments are flowering earlier that irrigated
A29: =C47 -> 29AprIrrigated | B29: 45411 | C29: =B29-$B$1 -> 119 | D29: =D47-D8 -> 104.33333 | E29: =E47-E8 -> 118 | F29: =F47-F8 -> 87 | G29: =G47-G8 -> 102.33333 | H29: =H47-H8 -> 110.66667 | I29: =I47-I8 -> 93.333333 | J29: =J47-J8 -> 107.33333 | K29: =K47-K8 -> 83.666667 | ... W29: =W47-W8 -> 114
A30: =C44 -> 6JunIrrigated | B30: 45449 | C30: =B30-$B$1 -> 157 | D30: =D44-D5 -> 88.333333 | E30: =E44-E5 -> 90.666667 | F30: =F44-F5 -> 84 | G30: =G44-G5 -> 87.333333 | H30: =H44-H5 -> 87.666667 | I30: =I44-I5 -> 82.333333 | J30: =J44-J5 -> 90.333333 | K30: =K44-K5 -> 82.333333 | ... W30: =W44-W5 -> 90.666667
A31: =C49 -> 24JunIrrigated | B31: 45467 | C31: =B31-$B$1 -> 175 | D31: =D49-D10 -> 76.333333 | E31: =E49-E10 -> 81.5 | F31: =F49-F10 -> 71.666667 | G31: =G49-G10 -> 74 | H31: =H49-H10 -> 78.5 | I31: =I49-I10 -> 72.666667 | J31: =J49-J10 -> 75 | K31: =K49-K10 -> 70 | ... S31: =S49-S10 -> 72.5 | U31: =U49-U10 -> 78.333333 | V31: =V49-V10 -> 85 | W31: =W49-W10 -> 76.5
A33: =C43 -> 24AprRainout | B33: 45406 | C33: =B33-$B$1 -> 114 | D33: =(D43-D4)-D28 -> 5.3333333 | E33: =(E43-E4)-E28 -> -2.3333333 | F33: =(F43-F4)-F28 -> 0.33333333 | G33: =(G43-G4)-G28 -> 0.33333333 | H33: =(H43-H4)-H28 -> -13.666667 | I33: =(I43-I4)-I28 -> -2.6666667 | J33: =(J43-J4)-J28 -> -1.3333333 | K33: =(K43-K4)-K28 -> -1.6666667 | M33: =(M43-M4)-M28 -> 1 | N33: =(N43-N4)-N28 -> 1.3333333 | O33: =(O43-O4)-O28 -> -9.3333333 | P33: =(P43-P4)-P28 -> -1.6666667 | Q33: =(Q43-Q4)-Q28 -> -18.666667 | R33: =(R43-R4)-R28 -> -3 | S33: =(S43-S4)-S28 -> -12.666667 | T33: =(T43-T4)-T28 -> -8.3333333 | ... W33: =(W43-W4)-W28 -> -2.3333333
A34: =C48 -> 29AprRainout | B34: 45411 | C34: =B34-$B$1 -> 119 | D34: =(D48-D9)-D29 -> -0.66666667 | E34: =(E48-E9)-E29 -> -7 | F34: =(F48-F9)-F29 -> 2 | G34: =(G48-G9)-G29 -> -2.3333333 | H34: =(H48-H9)-H29 -> -1.6666667 | I34: =(I48-I9)-I29 -> -1.6666667 | J34: =(J48-J9)-J29 -> -2 | K34: =(K48-K9)-K29 -> 3.6666667 | ... W34: =(W48-W9)-W29 -> -3.6666667
A35: =C45 -> 6JunRainfed | B35: 45449 | C35: =B35-$B$1 -> 157 | D35: =(D45-D6)-D30 -> 0.66666667 | E35: =(E45-E6)-E30 -> 0 | F35: =(F45-F6)-F30 -> -3.6666667 | G35: =(G45-G6)-G30 -> 0 | H35: =(H45-H6)-H30 -> -1.6666667 | I35: =(I45-I6)-I30 -> -1.3333333 | J35: =(J45-J6)-J30 -> -2 | K35: =(K45-K6)-K30 -> -1.6666667 | ... W35: =(W45-W6)-W30 -> 0.33333333
A36: =C50 -> 24JunRainfed | B36: 45467 | C36: =B36-$B$1 -> 175 | D36: =(D50-D11)-D31 -> 5.6666667 | E36: =(E50-E11)-E31 -> 2.8333333 | F36: =(F50-F11)-F31 -> 3.6666667 | G36: =(G50-G11)-G31 -> 8 | H36: =(H50-H11)-H31 -> 14.833333 | I36: =(I50-I11)-I31 -> 6.3333333 | J36: =(J50-J11)-J31 -> 9.6666667 | K36: =(K50-K11)-K31 -> 1.6666667 | ... S36: =(S50-S11)-S31 -> 10.5 | U36: =(U50-U11)-U31 -> 7.6666667 | V36: =(V50-V11)-V31 -> 0.66666667 | W36: =(W50-W11)-W31 -> 5.5
C39: Average of Lentil.Phenology.StartOfFloweringDAS | D39: Column Labels
C40: Row Labels | D40: Ace | E40: Aldinga | F40: Blitz | G40: Bolt | H40: Boomer | I40: CIPAL0901 | J40: CIPAL1504 | K40: CIPAL1701 | L40: Commando | M40: Flash | N40: Giant | O40: Greenfield | P40: Hurricane | Q40: Indianhead | R40: Jumbo | S40: Jumbo2 | T40: Matilda | U40: Nipper | V40: Northfield | W40: Nugget
C41: Roseworthy2018
C42: 24AprIrrigated | D42: 99 | E42: 125.33333 | F42: 91 | G42: 100.66667 | H42: 111.66667 | I42: 98 | J42: 109.33333 | K42: 100.33333 | L42: 147.33333 | M42: 116.33333 | N42: 97 | O42: 113.66667 | P42: 104.66667 | Q42: 150 | R42: 124 | S42: 112 | T42: 116.66667 | U42: 137 | V42: 138.33333 | W42: 124.33333
C43: 24AprRainout | D43: 104.33333 | E43: 123 | F43: 91.333333 | G43: 101 | H43: 98 | I43: 95.333333 | J43: 108 | K43: 98.666667 | M43: 117.33333 | N43: 98.333333 | O43: 104.33333 | P43: 103 | Q43: 131.33333 | R43: 121 | S43: 99.333333 | T43: 108.33333 | U43: 126 | V43: 128 | W43: 122
C44: 6JunIrrigated | D44: 101.33333 | E44: 103.66667 | F44: 97 | G44: 100.33333 | H44: 100.66667 | I44: 95.333333 | J44: 103.33333 | K44: 95.333333 | L44: 124 | M44: 103.66667 | N44: 100.66667 | O44: 102.33333 | P44: 104.66667 | Q44: 119 | R44: 101.66667 | S44: 99.666667 | T44: 102.33333 | U44: 105.66667 | V44: 104.33333 | W44: 103.66667
C45: 6JunRainfed | D45: 102 | E45: 103.66667 | F45: 93.333333 | G45: 100.33333 | H45: 99 | I45: 94 | J45: 101.33333 | K45: 93.666667 | L45: 125 | M45: 99 | N45: 96.333333 | O45: 102.66667 | P45: 103.33333 | Q45: 122.33333 | R45: 101.33333 | S45: 100.66667 | T45: 102 | U45: 106.33333 | V45: 104.66667 | W45: 104
C46: Roseworthy2019
C47: 29AprIrrigated | D47: 116.33333 | E47: 130 | F47: 99 | G47: 114.33333 | H47: 122.66667 | I47: 105.33333 | J47: 119.33333 | K47: 95.666667 | L47: 162 | M47: 119 | N47: 111.33333 | O47: 116.33333 | P47: 118.33333 | Q47: 157.66667 | R47: 119.66667 | S47: 119.66667 | T47: 125.33333 | U47: 132 | V47: 134 | W47: 126
...

Sheet MetData
A1: Date | B1: year | C1: day | D1: radn | E1: maxt | F1: mint | G1: rain | H1: evap | I1: vp | J1: code | K1: Tt | L1: TtAcum
C2: () | D2: () | E2: (MJ/m^2) | F2: (oC) | G2: (oC) | H2: (mm) | I2: (mm) | J2: (hPa) | K2: ()
A3: =DATE(B3,1,C3) -> 43101 | B3: 2018 | C3: 1 | D3: 27.3 | E3: 26.2 | F3: 12 | G3: 0 | H3: 8.4 | I3: 14.2 | J3: 422222 | K3: =(MAX(0,F3-2)+MAX(0,E3-2))/2 -> 17.1 | L3: =K3 -> 17.1
A4: =DATE(B4,1,C4) -> 43102 | B4: 2018 | C4: 2 | D4: 23.4 | E4: 24.7 | F4: 12.3 | G4: 0 | H4: 8.2 | I4: 13.8 | J4: 422222 | K4: =(MAX(0,F4-2)+MAX(0,E4-2))/2 -> 16.5 | L4: =K4+L3 -> 33.6
A5: =DATE(B5,1,C5) -> 43103 | B5: 2018 | C5: 3 | D5: 29.1 | E5: 26.9 | F5: 13.2 | G5: 0 | H5: 7.7 | I5: 10.5 | J5: 422222 | K5: =(MAX(0,F5-2)+MAX(0,E5-2))/2 -> 18.05 | L5: =K5+L4 -> 51.65
A6: =DATE(B6,1,C6) -> 43104 | B6: 2018 | C6: 4 | D6: 29.8 | E6: 33.5 | F6: 11.8 | G6: 0 | H6: 9.1 | I6: 11.8 | J6: 422222 | K6: =(MAX(0,F6-2)+MAX(0,E6-2))/2 -> 20.65 | L6: =K6+L5 -> 72.3
A7: =DATE(B7,1,C7) -> 43105 | B7: 2018 | C7: 5 | D7: 30.1 | E7: 38.9 | F7: 13.4 | G7: 0 | H7: 10.7 | I7: 10.3 | J7: 422222 | K7: =(MAX(0,F7-2)+MAX(0,E7-2))/2 -> 24.15 | L7: =K7+L6 -> 96.45
A8: =DATE(B8,1,C8) -> 43106 | B8: 2018 | C8: 6 | D8: 30 | E8: 43.8 | F8: 21.5 | G8: 0 | H8: 17.1 | I8: 7.3 | J8: 422222 | K8: =(MAX(0,F8-2)+MAX(0,E8-2))/2 -> 30.65 | L8: =K8+L7 -> 127.1
A9: =DATE(B9,1,C9) -> 43107 | B9: 2018 | C9: 7 | D9: 27 | E9: 32.7 | F9: 15.8 | G9: 0 | H9: 7.5 | I9: 14.2 | J9: 422222 | K9: =(MAX(0,F9-2)+MAX(0,E9-2))/2 -> 22.25 | L9: =K9+L8 -> 149.35
A10: =DATE(B10,1,C10) -> 43108 | B10: 2018 | C10: 8 | D10: 27.2 | E10: 29.6 | F10: 15.6 | G10: 0 | H10: 8.1 | I10: 14.1 | J10: 422222 | K10: =(MAX(0,F10-2)+MAX(0,E10-2))/2 -> 20.6 | L10: =K10+L9 -> 169.95
A11: =DATE(B11,1,C11) -> 43109 | B11: 2018 | C11: 9 | D11: 29.3 | E11: 28.3 | F11: 8.8 | G11: 0 | H11: 8.7 | I11: 13.4 | J11: 422222 | K11: =(MAX(0,F11-2)+MAX(0,E11-2))/2 -> 16.55 | L11: =K11+L10 -> 186.5
A12: =DATE(B12,1,C12) -> 43110 | B12: 2018 | C12: 10 | D12: 7.9 | E12: 29.8 | F12: 13.2 | G12: 0 | H12: 5.7 | I12: 9.2 | J12: 422222 | K12: =(MAX(0,F12-2)+MAX(0,E12-2))/2 -> 19.5 | L12: =K12+L11 -> 206
A13: =DATE(B13,1,C13) -> 43111 | B13: 2018 | C13: 11 | D13: 17.9 | E13: 38 | F13: 16.2 | G13: 0 | H13: 8.6 | I13: 8.6 | J13: 422222 | K13: =(MAX(0,F13-2)+MAX(0,E13-2))/2 -> 25.1 | L13: =K13+L12 -> 231.1
A14: =DATE(B14,1,C14) -> 43112 | B14: 2018 | C14: 12 | D14: 4.8 | E14: 22.1 | F14: 21.1 | G14: 1.9 | H14: 3.9 | I14: 21.8 | J14: 422222 | K14: =(MAX(0,F14-2)+MAX(0,E14-2))/2 -> 19.6 | L14: =K14+L13 -> 250.7
A15: =DATE(B15,1,C15) -> 43113 | B15: 2018 | C15: 13 | D15: 20.3 | E15: 22.8 | F15: 14.3 | G15: 0.1 | H15: 6 | I15: 14.5 | J15: 422222 | K15: =(MAX(0,F15-2)+MAX(0,E15-2))/2 -> 16.55 | L15: =K15+L14 -> 267.25
... A793: =DATE(B793,1,C793) -> 43891 | B793: 2020 | C793: 61 | D793: 18.1 | E793: 34.1 | F793: 14.2 | G793: 0 | H793: 7.1 | I793: 11.1 | J793: 422222 | K793: =(MAX(0,F793-2)+MAX(0,E793-2))/2 -> 22.15 | L793: =K793+L792 -> 12131.95

Sheet Observed
A1: SimulationName | B1: [Clock].Today | C1: Lentil.Phenology.CurrentStageName | D1: Lentil.Phenology.EmergenceDAS | E1: Lentil.Phenology.EmergenceDASError | F1: Lentil.Phenology.StartFloweringDAS | G1: Lentil.Phenology.StartFloweringDASError | H1: Lentil.Phenology.PodEmergenceDAS | I1: Lentil.Phenology.PodEmergenceDASError | J1: Lentil.Phenology.EndOfFloweringDAS | K1: Lentil.Phenology.EndOfFloweringDASError | L1: Lentil.Phenology.MaturityDAS | M1: Lentil.Phenology.MaturityDASError | N1: Lentil.Grain.Wt | O1: Lentil.Grain.WtError | P1: Lentil.AboveGround.Wt | Q1: Lentil.AboveGround.WtError | R1: Lentil.Grain.HarvestIndex | S1: Lentil.Grain.HarvestIndexError | T1: Lentil.Grain.Size | U1: Lentil.Grain.SizeError | V1: Lentil.Leaf.NodeNumber | W1: Lentil.Leaf.Number | X1: Lentil.LeavesPerPlant | Y1: Lentil.Leaf.LAI | Z1: Lentil.LAIError | AA1: Lentil.Leaf.SpecificArea | AB1: Lentil.Leaf.Wt | AC1: Lentil.Stem.Wt | AD1: Lentil.Leaf.WtError | AE1: Lentil.Stem.WtError | AF1: Lentil.PodsPerPlant | AG1: Soil.SoilWater.SW(1) | AH1: Soil.SoilWater.SW(2) | AI1: Soil.SoilWater.SW(3) | AJ1: Soil.SoilWater.SW(4) | AK1: Soil.SoilWater.SW(5) | AL1: Soil.SoilWater.SW(6) | AM1: Soil.SoilWater.SW(7) | AN1: Soil.SoilWater.SW(8) | AO1: Soil.SoilWater.SW(9) | AP1: Soil.SoilWater.SW(10) | AQ1: sum([Soil].Water.MM)
A2: RoseworthyTOSbyIrr24Apr2018IrrigatedCvAldinga | B2: 43423 | C2: HarvestRipe | D2: 9 | E2: 0 | F2: 125.33333 | G2: 4.0414519 | H2: 139.33333 | I2: 5.7735027 | J2: 186 | K2: 0 | L2: 210 | M2: 0 | N2: 203.76667 | O2: 41.778025 | P2: 699.6 | Q2: 176.34038 | R2: 0.29669154 | S2: 0.055737651 | T2: 0.039233333 | U2: 0.0070152215
A3: RoseworthyTOSbyIrr24Apr2018IrrigatedCvBoomer | B3: 43423 | C3: HarvestRipe | D3: 9 | E3: 0 | F3: 111.66667 | G3: 0.57735027 | H3: 123 | I3: 0 | J3: 186 | K3: 0 | L3: 210 | M3: 0 | N3: 176.36333 | O3: 31.394204 | P3: 1143.3333 | Q3: 72.913739 | R3: 0.15373272 | S3: 0.021250037 | T3: 0.0558 | U3: 0.0039038443
A4: RoseworthyTOSbyIrr24Apr2018IrrigatedCvCIPAL0901 | B4: 43423 | C4: HarvestRipe | D4: 9 | E4: 0 | F4: 98 | G4: 0 | H4: 111 | I4: 6.0827625 | J4: 162.33333 | K4: 20.502032 | L4: 210 | M4: 0 | N4: 233.19 | O4: 103.08084 | P4: 678.8 | Q4: 246.17652 | R4: 0.34900178 | S4: 0.10951891 | T4: 0.0432 | U4: 0.0020518285
A5: RoseworthyTOSbyIrr24Apr2018IrrigatedCvCIPAL1504 | B5: 43423 | C5: HarvestRipe | D5: 9 | E5: 0 | F5: 109.33333 | G5: 11.015141 | H5: 126.66667 | I5: 5.5075705 | J5: 186 | K5: 0 | L5: 210 | M5: 0 | N5: 216.15 | O5: 126.72828 | P5: 819.63333 | Q5: 270.5403 | R5: 0.24807208 | S5: 0.071332536 | T5: 0.042166667 | U5: 0.0041860881
A6: RoseworthyTOSbyIrr24Apr2018IrrigatedCvCIPAL1701 | B6: 43423 | C6: HarvestRipe | D6: 9 | E6: 0 | F6: 100.33333 | G6: 2.081666 | H6: 111.66667 | I6: 3.2145503 | J6: 186 | K6: 0 | L6: 210 | M6: 0 | N6: 368.08667 | O6: 38.900598 | P6: 928.16667 | Q6: 156.55856 | R6: 0.40022529 | S6: 0.036100905 | T6: 0.049933333 | U6: 0.0017925773
A7: RoseworthyTOSbyIrr24Apr2018IrrigatedCvCommando | B7: 43423 | C7: HarvestRipe | D7: 9 | E7: 0 | F7: 147.33333 | G7: 0.57735027 | H7: 170 | I7: 0 | J7: 191 | K7: 0 | L7: 210 | M7: 0 | N7: 112.38667 | O7: 27.016005 | P7: 970.56667 | Q7: 110.13384 | R7: 0.11576356 | S7: 0.025578175 | T7: 0.034333333 | U7: 0.0055895736
A8: RoseworthyTOSbyIrr24Apr2018IrrigatedCvIndianhead | B8: 43423 | C8: HarvestRipe | D8: 9 | E8: 0 | F8: 150 | G8: 2 | H8: 170 | I8: 0 | J8: 191 | K8: 0 | L8: 210 | M8: 0 | N8: 73.643333 | O8: 17.638068 | P8: 714.83333 | Q8: 164.92524 | R8: 0.10918097 | S8: 0.044549201 | T8: 0.018433333 | U8: 0.0036678786
A9: RoseworthyTOSbyIrr24Apr2018IrrigatedCvMatilda | B9: 43423 | C9: HarvestRipe | D9: 9 | E9: 0 | F9: 116.66667 | G9: 2.5166115 | H9: 128.33333 | I9: 1.5275252 | J9: 186 | K9: 0 | L9: 210 | M9: 0 | N9: 258.42 | O9: 88.196129 | P9: 1231.9333 | Q9: 362.00103 | R9: 0.20765133 | S9: 0.012140133 | T9: 0.048966667 | U9: 0.0021031722
A10: RoseworthyTOSbyIrr24Apr2018IrrigatedCvNipper | B10: 43423 | C10: HarvestRipe | D10: 9 | E10: 0 | F10: 137 | G10: 1 | H10: 145.33333 | I10: 1.1547005 | J10: 186 | K10: 0 | L10: 210 | M10: 0 | N10: 260.16667 | O10: 85.081157 | P10: 1029.4333 | Q10: 350.02715 | R10: 0.25552654 | S10: 0.026160662 | T10: 0.030333333 | U10: 0.0034019602
A11: RoseworthyTOSbyIrr24Apr2018IrrigatedCvNugget | B11: 43423 | C11: HarvestRipe | D11: 9 | E11: 0 | F11: 124.33333 | G11: 8.326664 | H11: 141 | I11: 6.9282032 | J11: 186 | K11: 0 | L11: 210 | M11: 0 | N11: 161.16667 | O11: 85.109479 | P11: 754.16667 | Q11: 269.88224 | R11: 0.20168691 | S11: 0.051776435 | T11: 0.0412 | U11: 0.0038039453
A12: RoseworthyTOSbyIrr24Apr2018IrrigatedCvNorthfield | B12: 43423 | C12: HarvestRipe | D12: 9 | E12: 0 | F12: 138.33333 | G12: 3.2145503 | H12: 154.66667 | I12: 13.279056 | J12: 186 | K12: 0 | L12: 210 | M12: 0 | N12: 360.25 | O12: 78.223382 | P12: 1092.6667 | Q12: 120.76975 | R12: 0.32746421 | S12: 0.038263399 | T12: 0.032566667 | U12: 0.0031628047
A13: RoseworthyTOSbyIrr24Apr2018IrrigatedCvAce | B13: 43423 | C13: HarvestRipe | D13: 9 | E13: 0 | F13: 99 | G13: 1.7320508 | H13: 110.66667 | I13: 3.2145503 | J13: 186 | K13: 0 | L13: 210 | M13: 0 | N13: 231.41333 | O13: 40.328483 | P13: 982.3 | Q13: 59.727464 | R13: 0.23748362 | S13: 0.054568193 | T13: 0.041733333 | U13: 0.00046188022
... A44: RoseworthyTOSbyIrr6Jun2018IrrigatedCvCIPAL0901 | B44: 43397 | C44: HarvestRipe | D44: 13 | E44: 0 | F44: 95.333333 | G44: 2.8867513 | H44: 104.33333 | I44: 2.3094011 | J44: 127 | K44: 2.6457513 | L44: 141.66667 | M44: 6.6583281 | N44: 126.03828 | O44: 20.252268 | P44: 535.5 | Q44: 47.376154 | R44: 0.21651076 | S44: 0.0095104512 | T44: 0.04239 | U44: 0.0017111984
A45: RoseworthyTOSbyIrr6Jun2018IrrigatedCvCIPAL1504 | B45: 43401 | C45: HarvestRipe | D45: 13 | E45: 0 | F45: 103.33333 | G45: 1.1547005 | H45: 105 | I45: 17.320508 | J45: 130 | K45: 0 | L45: 145.66667 | M45: 5.7735027 | N45: 124.20664 | O45: 20.677902 | P45: 675 | R45: 0.2056713 | T45: 0.036805 | U45: 0.0040941483
A46: RoseworthyTOSbyIrr6Jun2018IrrigatedCvCIPAL1701 | B46: 43393 | C46: HarvestRipe | D46: 13 | E46: 0 | F46: 95.333333 | G46: 2.8867513 | H46: 104.33333 | I46: 1.5275252 | J46: 124 | K46: 1 | L46: 137 | M46: 0 | N46: 106.5263 | O46: 33.069574 | P46: 555.33333 | Q46: 138.12072 | R46: 0.19009481 | S46: 0.016594231 | T46: 0.040133333 | U46: 0.0018502252
A47: RoseworthyTOSbyIrr6Jun2018IrrigatedCvCommando | B47: 43405 | C47: HarvestRipe | D47: 13 | E47: 0 | F47: 124 | G47: 1.7320508 | H47: 127.66667 | I47: 1.1547005 | J47: 142.66667 | K47: 10.969655 | L47: 149 | M47: 0 | N47: 32.880208 | O47: 8.3493856 | P47: 451.33333 | Q47: 53.313538 | R47: 0.074999313 | S47: 0.027392425 | T47: 0.0326 | U47: 0.0018083141
A48: RoseworthyTOSbyIrr6Jun2018IrrigatedCvIndianhead | B48: 43405 | C48: HarvestRipe | D48: 13 | E48: 0 | F48: 119 | G48: 10.392305 | H48: 125.33333 | I48: 2.8867513 | J48: 149 | K48: 0 | L48: 149 | M48: 0 | N48: 59.054688 | O48: 71.053183 | P48: 518.5 | Q48: 249.60869 | R48: 0.091514617 | S48: 0.092980403 | T48: 0.0302 | U48: 0.014142136
A49: RoseworthyTOSbyIrr6Jun2018IrrigatedCvMatilda | B49: 43401 | C49: HarvestRipe | D49: 13 | E49: 0 | F49: 102.33333 | G49: 1.1547005 | H49: 112.33333 | I49: 2.3094011 | J49: 129.66667 | K49: 3.5118846 | L49: 145 | M49: 6.9282032 | N49: 142.60417 | O49: 40.210045 | P49: 807 | Q49: 199.34643 | R49: 0.17620966 | S49: 0.013057245 | T49: 0.044523333 | U49: 0.0032524811
A50: RoseworthyTOSbyIrr6Jun2018IrrigatedCvNipper | B50: 43402 | C50: HarvestRipe | D50: 13 | E50: 0 | F50: 105.66667 | G50: 2.081666 | H50: 115 | I50: 0 | J50: 128.66667 | K50: 2.3094011 | L50: 146.33333 | M50: 4.6188022 | N50: 108.03333 | O50: 24.918129 | P50: 517.5 | Q50: 75.660426 | R50: 0.18250688 | S50: 0.011204549 | T50: 0.03105 | U50: 0.00091923882
A51: RoseworthyTOSbyIrr6Jun2018IrrigatedCvNugget | B51: 43401 | C51: HarvestRipe | D51: 13 | E51: 0 | F51: 103.66667 | G51: 0.57735027 | H51: 115 | I51: 0 | J51: 130 | K51: 0 | L51: 145.66667 | M51: 5.7735027 | N51: 87.960938 | O51: 13.031735 | P51: 489.33333 | Q51: 88.325157 | R51: 0.18056012 | S51: 0.0070532423 | T51: 0.037766667 | U51: 0.0004163332
A52: RoseworthyTOSbyIrr6Jun2018IrrigatedCvNorthfield | B52: 43402 | C52: HarvestRipe | D52: 13 | E52: 0 | F52: 104.33333 | G52: 2.3094011 | H52: 117.33333 | I52: 4.0414519 | J52: 130 | K52: 0 | L52: 146 | M52: 5.1961524 | N52: 117.42188 | O52: 69.007488 | P52: 455 | Q52: 89.095454 | R52: 0.17285856 | S52: 0.022848181 | T52: 0.0316 | U52: 0.00056568542
A53: RoseworthyTOSbyIrr6Jun2018IrrigatedCvAce | B53: 43401 | C53: HarvestRipe | D53: 13 | E53: 0 | F53: 101.33333 | G53: 1.1547005 | H53: 112.66667 | I53: 4.0414519 | J53: 128 | K53: 3.4641016 | L53: 145 | M53: 6.9282032 | N53: 109.86198 | O53: 15.611178 | P53: 620.33333 | Q53: 121.25318 | R53: 0.17846893 | S53: 0.010894595 | T53: 0.0373 | U53: 0.0026888659
A54: RoseworthyTOSbyIrr6Jun2018IrrigatedCvBlitz | B54: 43399 | C54: HarvestRipe | D54: 13 | E54: 0 | F54: 97 | G54: 0 | H54: 105 | I54: 1 | J54: 130.33333 | K54: 0.57735027 | L54: 143 | M54: 5.2915026 | N54: 137.34375 | O54: 9.5017474 | P54: 748.5 | Q54: 60.104076 | R54: 0.18357415 | S54: 0.0020465029 | T54: 0.04165 | U54: 0.0023334524
A55: RoseworthyTOSbyIrr6Jun2018IrrigatedCvBolt | B55: 43401 | C55: HarvestRipe | D55: 13 | E55: 0 | F55: 100.33333 | G55: 1.5275252 | H55: 112.33333 | I55: 2.3094011 | J55: 131.33333 | K55: 7.0945989 | L55: 145.33333 | M55: 6.350853 | N55: 156.84141 | O55: 81.235971 | P55: 1001 | Q55: 625.08239 | R55: 0.18964976 | S55: 0.022733123 | T55: 0.039843333 | U55: 0.0014413998
A56: RoseworthyTOSbyIrr6Jun2018IrrigatedCvFlash | B56: 43402 | C56: HarvestRipe | D56: 13 | E56: 0 | F56: 103.66667 | G56: 2.081666 | H56: 115.66667 | I56: 8.0829038 | J56: 130.66667 | K56: 1.1547005 | L56: 146.33333 | M56: 4.6188022 | N56: 118.53021 | O56: 71.455795 | P56: 572.33333 | Q56: 296.09514 | R56: 0.20011082 | S56: 0.02570398 | T56: 0.04339 | U56: 0.0046858617
A57: RoseworthyTOSbyIrr6Jun2018IrrigatedCvGreenfield | B57: 43402 | C57: HarvestRipe | D57: 13 | E57: 0 | F57: 102.33333 | G57: 2.081666 | H57: 113.66667 | I57: 2.3094011 | J57: 136.33333 | K57: 10.969655 | L57: 146.33333 | M57: 4.6188022 | N57: 108.84115 | O57: 46.270918 | P57: 673.66667 | Q57: 317.27328 | R57: 0.16364587 | S57: 0.0070330545 | T57: 0.049833333 | U57: 0.0011503623
... A149: RoseworthyTOSbyIrr24Jun2019RainfedCvNipper | B149: 43780 | C149: HarvestRipe | D149: 14 | E149: 0 | F149: 100 | G149: 0 | H149: 105 | I149: 0 | J149: 124 | K149: 0 | L149: 141 | M149: 0 | N149: 183.95172 | O149: 55.520074 | P149: 560.71552 | Q149: 164.73881 | R149: 0.32766222 | S149: 0.0027489668 | T149: 0.02795 | U149: 0.0033234019
A150: RoseworthyTOSbyIrr24Jun2019RainfedCvNugget | B150: 43769 | C150: HarvestRipe | D150: 14 | E150: 0 | F150: 96 | G150: 0 | H150: 101 | I150: 0 | J150: 124 | K150: 0 | L150: 130 | M150: 0 | N150: 230.32759 | P150: 701.11034 | R150: 0.32851831 | T150: 0.0355
A151: RoseworthyTOSbyIrr24Jun2019RainfedCvNorthfield | B151: 43780 | C151: HarvestRipe | D151: 14 | E151: 0 | F151: 99.666667 | G151: 2.3094011 | H151: 105.33333 | I151: 2.8867513 | J151: 124 | K151: 0 | L151: 141 | M151: 0 | N151: 169.74138 | O151: 32.498348 | P151: 591.11724 | Q151: 64.156916 | R151: 0.28573815 | S151: 0.029501419 | T151: 0.026566667 | U151: 0.0006350853
A152: RoseworthyTOSbyIrr24Jun2019RainfedCvAce | B152: 43776 | C152: HarvestRipe | D152: 14 | E152: 0 | F152: 96 | G152: 4.3588989 | H152: 102.66667 | I152: 3.2145503 | J152: 122.33333 | K152: 2.8867513 | L152: 137 | M152: 6.9282032 | N152: 168.73448 | O152: 41.356676 | P152: 620.24828 | Q152: 21.601527 | R152: 0.27267593 | S152: 0.068932209 | T152: 0.040166667 | U152: 0.004315476
A153: RoseworthyTOSbyIrr24Jun2019RainfedCvBlitz | B153: 43772 | C153: HarvestRipe | D153: 14 | E153: 0 | F153: 89.333333 | G153: 5.7735027 | H153: 106.66667 | I153: 15.30795 | J153: 119.66667 | K153: 3.7859389 | L153: 133.33333 | M153: 6.6583281 | N153: 194.13103 | O153: 14.522042 | P153: 577.96207 | Q153: 176.29035 | R153: 0.35261048 | S153: 0.082384559 | T153: 0.0385 | U153: 0.001473092
A154: RoseworthyTOSbyIrr24Jun2019RainfedCvBolt | B154: 43780 | C154: HarvestRipe | D154: 14 | E154: 0 | F154: 96 | G154: 1 | H154: 102 | I154: 1 | J154: 124 | K154: 0 | L154: 141 | M154: 0 | N154: 200.71724 | O154: 21.690226 | P154: 676.61034 | Q154: 29.784967 | R154: 0.29610845 | S154: 0.018709281 | T154: 0.039233333 | U154: 0.00098149546
A155: RoseworthyTOSbyIrr24Jun2019RainfedCvFlash | B155: 43780 | C155: HarvestRipe | D155: 14 | E155: 0 | F155: 105 | G155: 14.071247 | H155: 103.25 | I155: 1.8929694 | J155: 124 | K155: 0 | L155: 141 | M155: 0 | N155: 233.61724 | O155: 27.573315 | P155: 741.83017 | Q155: 177.90139 | R155: 0.32191579 | S155: 0.042400806 | T155: 0.0414 | U155: 0.0017907168
A156: RoseworthyTOSbyIrr24Jun2019RainfedCvGreenfield | B156: 43780 | C156: HarvestRipe | D156: 14 | E156: 0 | F156: 97.333333 | G156: 0.57735027 | H156: 103 | I156: 1.7320508 | J156: 120.66667 | K156: 2.8867513 | L156: 141 | M156: 0 | N156: 206.41724 | O156: 60.269443 | P156: 752.87586 | Q156: 234.57982 | R156: 0.27535105 | S156: 0.030478935 | T156: 0.043866667 | U156: 0.0016258331
A157: RoseworthyTOSbyIrr24Jun2019RainfedCvGiant | B157: 43780 | C157: HarvestRipe | D157: 14 | E157: 0 | F157: 93 | G157: 4 | H157: 100 | I157: 3.6055513 | J157: 124 | K157: 0 | L157: 141 | M157: 0 | N157: 153.94138 | O157: 41.210288 | P157: 733.69655 | Q157: 196.89197 | R157: 0.20991431 | S157: 0.0084158242 | T157: 0.048266667 | U157: 0.0060135957
A158: RoseworthyTOSbyIrr24Jun2019RainfedCvHurricane | B158: 43780 | C158: HarvestRipe | D158: 14 | E158: 0 | F158: 99 | G158: 0 | H158: 104.66667 | I158: 0.57735027 | J158: 124 | K158: 0 | L158: 141 | M158: 0 | N158: 181.56207 | O158: 14.881472 | P158: 604.94828 | Q158: 30.553412 | R158: 0.29982653 | S158: 0.010909523 | T158: 0.029933333 | U158: 0.0011718931
A159: RoseworthyTOSbyIrr24Jun2019RainfedCvJumbo | B159: 43780 | C159: HarvestRipe | D159: 14 | E159: 0 | F159: 96.666667 | G159: 2.081666 | H159: 103.33333 | I159: 2.081666 | J159: 124 | K159: 0 | L159: 141 | M159: 0 | N159: 234.04828 | O159: 42.269176 | P159: 706.71379 | Q159: 24.304864 | R159: 0.33147147 | S159: 0.062357524 | T159: 0.0414 | U159: 0.0011269428
A160: RoseworthyTOSbyIrr24Jun2019RainfedCvJumbo2 | B160: 43777 | C160: HarvestRipe | D160: 14 | E160: 0 | F160: 97 | G160: 0.81649658 | H160: 102.5 | I160: 1.2909944 | J160: 124 | K160: 0 | L160: 138 | M160: 6 | N160: 145.39914 | O160: 91.727769 | P160: 567.18103 | Q160: 122.79111 | R160: 0.26847168 | S160: 0.1579527 | T160: 0.0432 | U160: 0.0040628397
A161: Emerald19TOS1CvBolt | B161: 43743 | C161: HarvestRipe | F161: 62.333333 | H161: 77.333333 | L161: 118 | N161: 138.40325 | O161: 9.2905251 | P161: 491.06667 | R161: 0.28384296
...
